Workbook

Sheet Claim Sheet
A1: Task ID | B1: Force Claim Link | C1: Claimed By | D1: What Was Fixed | E1: AHT (mins) | F1: Claude Score | G1: Claude Feedback | H1: Claude Feedback | I1: Eval Tool | J1: Eval Score | K1: Date fixed | L1: Too Simple | M1: Task Completed | N1: Sent Back for Fixes
A2: 7a807980-2578-4689-9a0a-784ea3d33e86 | B2: =concat("https://www.tsip.ai/force/",A2) -> https://www.tsip.ai/force/7a807980-2578-4689-9a0a-784ea3d33e86 | C2: John W | D2: vlookup returning wrong value for JG europe, fixed | updated prompt | fixed output/input | E2: 70 | F2: generate in-task | G2: generate in-task | H2: generate in-task | I2: generate in-task | J2: generate in-task | K2: 46160 | L2: FALSE | M2: TRUE
A3: 44ac67cb-1bb6-4667-8756-b22d439ca759 | B3: =concat("https://www.tsip.ai/force/",A3) -> https://www.tsip.ai/force/44ac67cb-1bb6-4667-8756-b22d439ca759 | C3: Nadine M | D3: redid prompt, fixed formatting and hardcoding issues in workbook. refined rubric (no stacking) and now aligns with prompt and workbook. | E3: 50 | F3: generate in-task | G3: generate in-task | H3: generate in-task | I3: generate in-task | J3: generate in-task | K3: 46161 | L3: FALSE | M3: TRUE
A4: 65be1d3a-83f6-4e28-9f85-b3a419a84fd6 | B4: =concat("https://www.tsip.ai/force/",A4) -> https://www.tsip.ai/force/65be1d3a-83f6-4e28-9f85-b3a419a84fd6 | C4: Ariya S | D4: workbook fixes based on claude feedback; rubric: added model integration and minor fixes across other sections | E4: 35 | F4: generate in-task | G4: generate in-task | H4: generate in-task | I4: generate in-task | J4: generate in-task | K4: 46160 | M4: TRUE
A5: 2f1fdba6-a805-483f-810e-035773eb691d | B5: =concat("https://www.tsip.ai/force/",A5) -> https://www.tsip.ai/force/2f1fdba6-a805-483f-810e-035773eb691d | C5: Elliot S | D5: redid prompt, fixed claude issues, and rubric | E5: 65 | F5: generate in-task | G5: generate in-task | H5: generate in-task | I5: generate in-task | J5: generate in-task | K5: 46160 | L5: FALSE | M5: TRUE
A6: 295e3612-cb62-4eaf-b87a-96708f62d7c2 | B6: =concat("https://www.tsip.ai/force/",A6) -> https://www.tsip.ai/force/295e3612-cb62-4eaf-b87a-96708f62d7c2 | C6: John W | D6: workbook fixes, prompt edit, created model integration + output validation | E6: 70 | F6: generate in-task | G6: generate in-task | H6: generate in-task | I6: generate in-task | J6: generate in-task | K6: 46160 | L6: FALSE | M6: TRUE
A7: 16e3ef61-3f9c-4ac7-b32f-4823bbc356f7 | B7: =concat("https://www.tsip.ai/force/",A7) -> https://www.tsip.ai/force/16e3ef61-3f9c-4ac7-b32f-4823bbc356f7 | C7: Ariya S | D7: workbook, prompt, and rubric small fixes from claude feedback | E7: 50 | F7: generate in-task | G7: generate in-task | H7: generate in-task | I7: generate in-task | J7: generate in-task | K7: 46160 | L7: FALSE | M7: TRUE
A8: aad52b58-4443-48b3-918d-98c1742f1df1 | B8: =concat("https://www.tsip.ai/force/",A8) -> https://www.tsip.ai/force/aad52b58-4443-48b3-918d-98c1742f1df1 | C8: Ariya S | D8: fixes to workbook based on claude feedback, rubric fixes resulting from that | E8: 70 | F8: generate in-task | G8: generate in-task | H8: generate in-task | I8: generate in-task | J8: generate in-task | K8: 46160 | L8: FALSE | M8: TRUE
A9: 8a831111-f767-4ed0-95e2-7f69615d0959 | B9: =concat("https://www.tsip.ai/force/",A9) -> https://www.tsip.ai/force/8a831111-f767-4ed0-95e2-7f69615d0959 | C9: Diogo P | D9: Major changes to input and output workbook. Both had linked cells to blank cells. Part of prompt didn't correspond to what was happening in the model. | E9: 100 | F9: generate in-task | G9: generate in-task | H9: generate in-task | I9: generate in-task | J9: generate in-task | K9: 46162 | L9: FALSE | M9: TRUE
A10: bc059c29-6c77-45f1-8172-fdbe6d1c4d42 | B10: =concat("https://www.tsip.ai/force/",A10) -> https://www.tsip.ai/force/bc059c29-6c77-45f1-8172-fdbe6d1c4d42 | C10: Antonio V | D10: Required significant work throughout | E10: 240 | F10: generate in-task | G10: generate in-task | H10: generate in-task | I10: generate in-task | J10: generate in-task | K10: 46160 | L10: FALSE | M10: TRUE
A11: f5f33709-656b-4730-bf27-54d886510a8a | B11: =concat("https://www.tsip.ai/force/",A11) -> https://www.tsip.ai/force/f5f33709-656b-4730-bf27-54d886510a8a | C11: Francisco C | D11: Output: Typo on FCF calculation with change in invested capital as a positive. This was corrected but there was no impact on valuation | Input: Removed unatural progression - Summary valuation already had the output from the task | Prompt: Minor changes | Rubric: Corrected output and perturbation sections; Removed duplicated and out of scope | E11: 70 | F11: generate in-task | G11: generate in-task | H11: generate in-task | I11: generate in-task | J11: generate in-task | K11: 46160 | L11: FALSE | M11: TRUE
A12: bf86fd2e-3e2d-4d0f-a173-db297660e072 | B12: =concat("https://www.tsip.ai/force/",A12) -> https://www.tsip.ai/force/bf86fd2e-3e2d-4d0f-a173-db297660e072 | C12: Francisco C | D12: Input: Removed hardcoded inputs on BS that were not natural progression | Output: Simplified assumption on goodwill amortization (was already calculated in the model); Few minor edits | Prompt: Removed incorrect hardcode for goodwill amortization; Simplified grammar | Rubric: Corrected wrong output validation criterion; Removed out of scope | E12: 55 | F12: generate in-task | G12: generate in-task | H12: generate in-task | I12: generate in-task | J12: generate in-task | K12: 46160 | L12: FALSE | M12: TRUE
A13: 5452a654-d533-46eb-b47f-1357a47eeca6 | B13: =concat("https://www.tsip.ai/force/",A13) -> https://www.tsip.ai/force/5452a654-d533-46eb-b47f-1357a47eeca6 | C13: Elliot S | D13: fixed rubric + logical progression of input to output by removing dependencies | E13: 60 | F13: generate in-task | G13: generate in-task | H13: generate in-task | I13: generate in-task | J13: generate in-task | K13: 46161 | L13: FALSE | M13: TRUE
A14: 91f0eaf1-2d4b-41ab-a262-8453686cea5a | B14: =concat("https://www.tsip.ai/force/",A14) -> https://www.tsip.ai/force/91f0eaf1-2d4b-41ab-a262-8453686cea5a | C14: Pragyat A | D14: Minor changes in prompt, model and rubrics | E14: 65 | F14: generate in-task | G14: generate in-task | H14: generate in-task | I14: generate in-task | J14: generate in-task | K14: 46163 | L14: FALSE | M14: TRUE
A15: cf573523-a0a1-40fb-ad40-b6b41b27ae3d | B15: =concat("https://www.tsip.ai/force/",A15) -> https://www.tsip.ai/force/cf573523-a0a1-40fb-ad40-b6b41b27ae3d | C15: Pragyat A | D15: Prompt, Rubric and output file. But their is issue in Input file too. regarding true values in check. | E15: 63 | F15: generate in-task | G15: generate in-task | H15: generate in-task | I15: generate in-task | J15: generate in-task | K15: 46163 | L15: FALSE | M15: TRUE
A16: e66fa748-66f4-4f25-b521-834f0ba81ff4 | B16: =concat("https://www.tsip.ai/force/",A16) -> https://www.tsip.ai/force/e66fa748-66f4-4f25-b521-834f0ba81ff4 | C16: Ariya S | D16: workbook fixes based on claude feedback;several prompt rewrites/reorganization; many rubric changes | E16: 70 | F16: generate in-task | G16: generate in-task | H16: generate in-task | I16: generate in-task | J16: generate in-task | K16: 46160 | L16: FALSE | M16: TRUE
... A18: 90bbed8a-b185-4f3d-96d0-b1527582ae9b | B18: =concat("https://www.tsip.ai/force/",A18) -> https://www.tsip.ai/force/90bbed8a-b185-4f3d-96d0-b1527582ae9b | C18: Ariya S | D18: workbook, prompt, and rubric fixes based on claude | E18: 50 | F18: generate in-task | G18: generate in-task | H18: generate in-task | I18: generate in-task | J18: generate in-task | K18: 46160 | L18: FALSE | M18: TRUE
A19: 0d9d675e-f3aa-4291-9183-9828fc1cca68 | B19: =concat("https://www.tsip.ai/force/",A19) -> https://www.tsip.ai/force/0d9d675e-f3aa-4291-9183-9828fc1cca68 | C19: Ariya S | D19: rubric to be regen (old format) | F19: generate in-task | G19: generate in-task | H19: generate in-task | I19: generate in-task | J19: generate in-task | L19: FALSE | M19: FALSE
A20: 74071b8e-e1a7-4815-9604-056c66f53fcd | B20: =concat("https://www.tsip.ai/force/",A20) -> https://www.tsip.ai/force/74071b8e-e1a7-4815-9604-056c66f53fcd | C20: Ariya S | D20: rubric fixes | E20: 45 | F20: generate in-task | G20: generate in-task | H20: generate in-task | I20: generate in-task | J20: generate in-task | K20: 46160 | L20: FALSE | M20: TRUE
A21: 5329fcc2-0bb8-4eaf-b563-54b64adf97da | B21: 2d607b4b-a8a1-41eb-a290-966ef66a1a8e | C21: Ava Z | D21: Workbook: fixed incorrectly locked cells, | F21: generate in-task | G21: generate in-task | H21: generate in-task | I21: generate in-task | J21: generate in-task | L21: FALSE | M21: FALSE
A22: 7e959336-04ed-49e4-bfef-665c0782448c | B22: =concat("https://www.tsip.ai/force/",A22) -> https://www.tsip.ai/force/7e959336-04ed-49e4-bfef-665c0782448c | C22: Ariya S | D22: fixes to workbook and rubric based on claude feedback | E22: 60 | F22: generate in-task | G22: generate in-task | H22: generate in-task | I22: generate in-task | J22: generate in-task | K22: 46160 | L22: FALSE | M22: TRUE
A23: a2cea33d-12d0-44ca-a889-a81ace87c570 | B23: =concat("https://www.tsip.ai/force/",A23) -> https://www.tsip.ai/force/a2cea33d-12d0-44ca-a889-a81ace87c570 | C23: Pragyat A | D23: Changes in Prompt, Rubric and Output file. | E23: 53 | F23: generate in-task | G23: generate in-task | H23: generate in-task | I23: generate in-task | J23: generate in-task | K23: 46163 | L23: FALSE | M23: TRUE
A24: e12b11cd-c4b1-416a-89cc-76419d8c598a | B24: =concat("https://www.tsip.ai/force/",A24) -> https://www.tsip.ai/force/e12b11cd-c4b1-416a-89cc-76419d8c598a | C24: Jalaj G | D24: prompt - minor changes workbook output - changed a few labels - added historical missing calcs rubric - unstacked fc criteria - removed out of scope criteria - added presentation criteria | E24: 60 | F24: generate in-task | G24: generate in-task | H24: generate in-task | I24: generate in-task | J24: generate in-task | K24: 46162 | L24: FALSE | M24: TRUE
A25: 62e771dc-72a6-41f0-9a53-41f396bef554 | B25: =concat("https://www.tsip.ai/force/",A25) -> https://www.tsip.ai/force/62e771dc-72a6-41f0-9a53-41f396bef554 | C25: Jalaj G | D25: prompt - added missing data - added missing calculation methodology - improved language throughout workbook output - several changes in labels and formulae - standardised formatting rubric - unstacked many criteria - added mi criteria - updated values of some ov and pt criteria - added presentation criteria | E25: 55 | F25: generate in-task | G25: generate in-task | H25: generate in-task | I25: generate in-task | J25: generate in-task | K25: 46161 | L25: FALSE | M25: TRUE
A26: 76d1c9fa-dcc0-4ae6-8d8a-54b7a3af800a | B26: =concat("https://www.tsip.ai/force/",A26) -> https://www.tsip.ai/force/76d1c9fa-dcc0-4ae6-8d8a-54b7a3af800a | C26: Jalaj G | D26: prompt - aligned analysis with actual workbook - entered missing hardcoded data - improved language throughout workbook output - applied consistent formatting rubric - unstacked many criteria - removed out of scope and superfluous criteria - added presentation criteria | E26: 65 | F26: generate in-task | G26: generate in-task | H26: generate in-task | I26: generate in-task | J26: generate in-task | K26: 46161 | L26: FALSE | M26: TRUE
A27: de0b9b68-3655-4ad8-b299-716ccea058fa | B27: =concat("https://www.tsip.ai/force/",A27) -> https://www.tsip.ai/force/de0b9b68-3655-4ad8-b299-716ccea058fa | C27: Jalaj G | D27: prompt - minor changes workbook output - updated formatting rubric - unstacked fc criteria - added mi criteria - removed out of scope criteria - added presentation criteria | E27: 55 | F27: generate in-task | G27: generate in-task | H27: generate in-task | I27: generate in-task | J27: generate in-task | K27: 46162 | L27: FALSE | M27: TRUE
A28: 9b77ed14-955e-476d-b455-9b9b4d7e0441 | B28: =concat("https://www.tsip.ai/force/",A28) -> https://www.tsip.ai/force/9b77ed14-955e-476d-b455-9b9b4d7e0441 | C28: Jalaj G | D28: prompt - rewrote completely - added missing inputs - added missing direction to delete tab workbook output - updated formatting - removed some hardcodes rubric - unstacked fc criteria - added mi criteria - corrected values of some ov and pt criteria - removed out of scope criteria - added presentation criteria | E28: 50 | F28: generate in-task | G28: generate in-task | H28: generate in-task | I28: generate in-task | J28: generate in-task | K28: 46162 | L28: FALSE | M28: TRUE
A29: 98424092-bac5-4483-9f0f-dcfa1df92519 | B29: =concat("https://www.tsip.ai/force/",A29) -> https://www.tsip.ai/force/98424092-bac5-4483-9f0f-dcfa1df92519 | C29: Jalaj G | D29: prompt - added missing calculation methodology - minor changes workbook output - changed formula in row 105 rubric - unstacked fc criteria - added mi criteria - added pt criteria - removed out of scope criteria - added presentation criteria | E29: 90 | F29: generate in-task | G29: generate in-task | H29: generate in-task | I29: generate in-task | J29: generate in-task | K29: 46161 | L29: FALSE | M29: TRUE
A30: 36e31d9a-2788-4c0b-816a-22f66623d6fd | B30: =concat("https://www.tsip.ai/force/",A30) -> https://www.tsip.ai/force/36e31d9a-2788-4c0b-816a-22f66623d6fd | C30: Jalaj G | D30: prompt - minor changes workbook output - changed formatting at a few places - corrected wrong linkages and formulae rubric - unstacked fc criteria - added mi criteria - corrected values of some ov and pt criteria - removed out of scope criteria - added presentation criteria | E30: 50 | F30: generate in-task | G30: generate in-task | H30: generate in-task | I30: generate in-task | J30: generate in-task | K30: 46162 | L30: FALSE | M30: TRUE
A31: 0a88b778-e4f3-418f-a39c-31aa94b7afa0 | B31: =concat("https://www.tsip.ai/force/",A31) -> https://www.tsip.ai/force/0a88b778-e4f3-418f-a39c-31aa94b7afa0 | C31: Jeff Z | D31: Model: Included SAP in all comps outputs (previously incorrect), renamed tab correctly Prompt: Tweaked prompt wording Rubric: Unstacked Pitfalls section, unstacked Presentation section, updated Perturbation to exact values, corrected rubric items for Output Validation section (for updated output workbook), standardized rubric for Model Integration section, updated scoring and labeling for the Formula Correctness section | E31: 45 | F31: 3 | G31: Run tsip-claude-feedback-ed0c7447-3724-4cda-9c27-4e1d044607af Completed May 18, 10:02 PM Major Takeaways The output workbook successfully builds the Comparable Company Analysis (CCA) tab from scratch and populates the Formatted Charts tab with correct cross-tab links. All six companies are present with correct company information, all financial metrics link dynamically to the respective Formatted tabs, EV/Revenue and EV/ARR formulas are correct (EV÷Revenue, EV÷ARR), the Implied Valuation section correctly multiplies CCA statistics by Snowflake's revenue/ARR, number formatting is professional (accounting format with $, 0.0"x" for multiples, bold blue section headers), and no error values exist in either key tab. However, there is a meaningful implementation error: the CCA summary statistics (C15:D19) use the range L6:L9/M6:M9 covering only four companies—Oracle, MongoDB, Atlassian, Autodesk—silently excluding SAP SE (row 10) from the peer set. The prompt explicitly says to exclude only Snowflake. The Formatted Charts median correctly uses MEDIAN(C5:C9), which includes all five peers (SAP SE included), creating an internal inconsistency within the output workbook itself. The task-specific rubric is internally inconsistent as a consequence: its formula correctness criteria state "computed from the peer set, excluding Snowflake" (implying all five peers), but its output validation expected values were derived from the four-company erroneous calculation, so a model producing the truly correct output would fail output validation. Major Errors CCA summary statistics use wrong peer set (L6:L9 instead of L6:L10): SAP SE (row 10) is excluded from MAX, PERCENTILE, MEDIAN, and MIN formulas in cells C15:D19. This contradicts the prompt instruction to use "only the peer set (Snowflake should be excluded)." The prompt lists six companies, five of which should form the peer set; only Snowflake should be excluded from the statistics. Internal inconsistency between CCA and Formatted Charts: The Formatted Charts median (C11/D11) correctly uses =MEDIAN(C5:C9) covering all five peers including SAP SE (producing EV/Revenue median of 8.46x and EV/ARR median of 10.02x), while the CCA stats use only four peers (EV/Revenue median 9.28x). The median values in these two sections do not agree for EV/Revenue. Rubric internal inconsistency: The formula correctness criteria (e.g., criteria IDs edadd311, 17d30dc2, 832aa785, 3029eaa6, 4a81e33f, 01712254) assert "computed exclusively from the peer set, excluding Snowflake," but the rubric's output validation expected values (9.28x median EV/Revenue; 19171.86 implied median EV/Revenue) are derived from the four-company set that excludes SAP SE. A model that correctly includes SAP SE in the CCA peer set would pass formula correctness but fail output validation; a model that replicates the error would fail formula correctness but pass output validation. Critical Errors SAP SE excluded from CCA summary statistics: The formulas =MAX(L6:L9), =PERCENTILE(L6:L9, 0.75), =MEDIAN(L6:L9), etc., should extend to L6:L10 to include SAP SE. This causes all five CCA summary statistics and all ten implied valuation values to be computed from the wrong peer set. The same four-range error is in the corresponding M6:M9 formulas for EV/ARR. This is the single change that moves the output from a "4" to a "3"—the analysis logic is structurally sound but quantitatively wrong relative to the prompt specification. Rubric output validation values calibrated to the erroneous output: Because the rubric's expected values (56484.83 max implied EV/ARR; 19171.86 median implied EV/Revenue; 9.28x CCA median EV/Revenue; 22065.76 75th-pct implied EV/Revenue; 17.87x 75th-pct EV/ARR) all match the four-peer calculation, a corrected output with SAP SE included would show different values (e.g., CCA median EV/Revenue ≈ 8.46x, implied median EV/Revenue ≈ 17,476) and fail output validation. This degraded rubric reliability prevents clean training signal. | H31: generate in-task | I31: generate in-task | J31: generate in-task | K31: 46163 | L31: FALSE | M31: TRUE
A32: d83d3eb8-99ca-4de7-9f98-991a81ce1147 | B32: =concat("https://www.tsip.ai/force/",A32) -> https://www.tsip.ai/force/d83d3eb8-99ca-4de7-9f98-991a81ce1147 | C32: Jalaj G | D32: feedback done, to complete on 5/21 | F32: generate in-task | G32: generate in-task | H32: generate in-task | I32: generate in-task | J32: generate in-task | L32: FALSE | M32: FALSE
A33: 2d607b4b-a8a1-41eb-a290-966ef66a1a8e | B33: =concat("https://www.tsip.ai/force/",A33) -> https://www.tsip.ai/force/2d607b4b-a8a1-41eb-a290-966ef66a1a8e | C33: Francisco C | D33: Output: Typo on one of the hardcodes for covid downside; removed the covenant and summary section to make the task more natural | Prompt: Minor adjustments | Rubric: Corrected most of validation and perturbation; Removed out of scope | E33: 65 | F33: generate in-task | G33: generate in-task | H33: generate in-task | I33: generate in-task | J33: generate in-task | K33: 46161 | L33: FALSE | M33: TRUE
A34: 45417e1e-19aa-4c6b-83e6-cd694026420d | B34: =concat("https://www.tsip.ai/force/",A34) -> https://www.tsip.ai/force/45417e1e-19aa-4c6b-83e6-cd694026420d | C34: Megan S | D34: Rubric did not match scope of output workbook, prompt rewritten + input workbook had to be recontextualized since it had hardcodes from the output workbook in it | E34: 90 | F34: generate in-task | G34: generate in-task | H34: generate in-task | I34: generate in-task | J34: generate in-task | K34: 46162 | L34: FALSE | M34: TRUE
A35: 108dc013-5e4c-4773-8379-c873684fe7ca | B35: =concat("https://www.tsip.ai/force/",A35) -> https://www.tsip.ai/force/108dc013-5e4c-4773-8379-c873684fe7ca | C35: Ava Z | D35: output workbook: fixed inconsistent decimals, corrected Other Rec calculation; fine turned prompt; rubric: revised formula checks | E35: 90 | F35: generate in-task | G35: generate in-task | H35: generate in-task | I35: generate in-task | J35: generate in-task | K35: 46161 | L35: FALSE | M35: TRUE
A36: bb995691-d4c3-4929-82e0-514c944b369a | B36: =concat("https://www.tsip.ai/force/",A36) -> https://www.tsip.ai/force/bb995691-d4c3-4929-82e0-514c944b369a | C36: Pragyat A | D36: Input, Prompt and rubric change | E36: 50 | F36: generate in-task | G36: generate in-task | H36: generate in-task | I36: generate in-task | J36: generate in-task | K36: 46163 | L36: FALSE | M36: TRUE
A37: ea0c47ab-e763-421c-b9cd-9d61c1e1c880 | B37: =concat("https://www.tsip.ai/force/",A37) -> https://www.tsip.ai/force/ea0c47ab-e763-421c-b9cd-9d61c1e1c880 | C37: Francisco C | D37: Input: Input was missing historical financials as mentioned by prompt; Corrected for natural progression (TV section had the outputs already pasted) | Output: Several typos across formulas, discounted cashflows missed the initial year, terminal value across the 2 methodologies was not discounted; Minor formatting typos | Prompt: Correction for alignment with new output | Rubric: Missing perturbation section, output section was mostly wrong; Other minor adjustements | E37: 90 | F37: generate in-task | G37: generate in-task | H37: generate in-task | I37: generate in-task | J37: generate in-task | K37: 46161 | L37: FALSE | M37: TRUE
A38: c3e5538c-d952-4ac9-9a99-7069e6438856 | B38: =concat("https://www.tsip.ai/force/",A38) -> https://www.tsip.ai/force/c3e5538c-d952-4ac9-9a99-7069e6438856 | C38: Jalaj G | D38: prompt - aligned all model values with prompt - added missing calculation methodology - improved language throughout workbook output - increased column widths - standardised formatting rubric - unstacked many criteria - added mi criteria - added pt criteria - added presentation criteria | E38: 80 | F38: generate in-task | G38: generate in-task | H38: generate in-task | I38: generate in-task | J38: generate in-task | K38: 46161 | L38: FALSE | M38: TRUE
A39: b66e0bf3-d738-4297-83dc-c19c545cf74c | B39: =concat("https://www.tsip.ai/force/",A39) -> https://www.tsip.ai/force/b66e0bf3-d738-4297-83dc-c19c545cf74c | C39: Jalaj G | D39: prompt - aligned all model values with prompt - removed unnecessary clutter - improved language throughout workbook output - aligned all model values with prompt - completed missing formulae - corrected wrong formulae - removed unnecessary clutter - simplified formatting a bit - standardised formatting rubric - unstacked many criteria - added mi criteria - corrected values of some ov and pt criteria - added presentation criteria | E39: 90 | F39: generate in-task | G39: generate in-task | H39: generate in-task | I39: generate in-task | J39: generate in-task | K39: 46161 | L39: FALSE | M39: TRUE
A40: 058b4565-71f7-4ebc-a015-b8c266077015 | B40: =concat("https://www.tsip.ai/force/",A40) -> https://www.tsip.ai/force/058b4565-71f7-4ebc-a015-b8c266077015 | C40: Spencer H | D40: workbook: addressed claude feedback prompt: had many repetitive hardcodes that were redundant; rewriting the logic for most lines since it is not explaining things correctly; didnt say any margin hardcodes rubric: fixed formula stacking; fixed perturbation issues | E40: 60 | F40: generate in-task | G40: generate in-task | H40: generate in-task | I40: generate in-task | J40: generate in-task | K40: 46161 | L40: FALSE | M40: TRUE
A41: 041e6f7f-5946-4fbd-8fb3-44b05aa05bfc | B41: =concat("https://www.tsip.ai/force/",A41) -> https://www.tsip.ai/force/041e6f7f-5946-4fbd-8fb3-44b05aa05bfc | C41: Antonio V | D41: Had to rebuild the whole exercise | E41: 120 | F41: generate in-task | G41: generate in-task | H41: generate in-task | I41: generate in-task | J41: generate in-task | K41: 46161 | L41: FALSE | M41: TRUE
...

Sheet Tasks to Send Back
A1: Task ID | B1: Claude Score | C1: Claude Feedback | D1: Rubric Tool | E1: Rubric Feedback
A2: Outcome | B2: Claude Score | C2: Claude Feedback | D2: Rubric Score | E2: Failed Criteria
A3: Send back to CB - Claude | B3: 3 | C3: # 1a694939-ce51-42dd-9273-d4121f1ffab0 **Score: 3 / 5** --- ## Major Takeaways The output workbook correctly builds the full Silver, Gold, and Platinum SAC breakdown by subscription type (rows 402–480), including all commission value formulas, Other SAC per-sub inputs, growth-rate projections, Total Other SAC capitalized lines, and the three amortization waterfalls with correct useful-life half-year conventions. All 11 output-validation benchmarks fall within the specified 2% tolerance, and all 7 perturbation tests pass at the tier level (Silver rows 428/430, Gold row 455, Platinum rows 478/480). No error values exist anywhere in the sheet. Formatting is largely correct—hardcoded inputs are blue, formula cells carry dark theme color (interpreted as black), dollar values show 2 decimal places with parentheses, and percentages use 0.0%. The critical defect is the projection-period aggregate section (rows 387–400): `Commission Value and Other SAC Value` (G391–K391), `Amortized Commissions and Other SAC` (G393–K393), `Other S&M` (G396–K396), and `Total S&M` (G400–K400) are all **hardcoded floats** rather than formula-linked sums. These cells feed the income statement (row 21, via row 400) and the non-GAAP and cash-flow sections (rows 51, 61, 68), so no upstream assumption change will flow into those sections. The hardcoded aggregate values also lack the blue font that should be applied to hardcoded inputs. --- ## Major Errors 1. **Hardcoded aggregate rows in the S&M rollup section (rows 391, 393, 396, 400, projection years G–K):** `G391:K391` (Commission Value & Other SAC aggregate), `G393:K393` (Amortized Commissions & Other SAC aggregate), `G396:K396` (Other S&M, which should equal Total Revenue × 4%), and `G400:K400` (Total S&M) are plain float values rather than formulas. Changing any upstream assumption (e.g., commission rate, inflation, subscriber counts) updates the tier-level SAC rows but leaves the income statement, non-GAAP metrics, and cash-flow statement unresponsive. 2. **Missing blue-font convention on projection-period hardcoded aggregate values:** The hardcoded cells in G391–K391, G393–K393, G396–K396, and G400–K400 carry the default theme color (interpreted as black/auto) rather than blue `#0000FF`. Hardcoded inputs in the existing workbook, and all other hardcoded inputs in the new section, correctly use blue; these aggregate rows are inconsistent. 3. **Minor number-format inconsistency:** Several intermediate rows (e.g., `Other SAC New Subs` row 414, `Other SAC Retention/Downgrade` row 416, amortization waterfall rows 422–426) use `#,##0.00_);(#,##0.00)` (no dollar-sign prefix) while the summary rows and adjacent dollar lines use `"$"#,##0.00_);("$"#,##0.00)`. Both formats meet the two-decimal, comma-separator, parentheses-for-negatives requirements, so this is cosmetic. --- ## Critical Errors - **Aggregate consolidation rows (391, 393, 396, 400) hardcoded in projection period:** This is the single most impactful defect. It fails three Formula Correctness rubric criteria (−4 pts) and the most heavily weighted Model Integration criterion (−4 pts). It also means the income statement, non-GAAP metrics, and cash-flow statement are silently disconnected from the new SAC schedule for all five forecast years. In a real analyst workflow this would be caught immediately and treated as a structural rebuild error. --- ## Rubric Rationale **Task-Specific Rubric (scored item by item):** | Section | Points Available | Points Earned | Notes | |---|---|---|---| | Formula Correctness | 26 | 22 | Fails items for aggregate Commission Value (1), aggregate Amortized SAC (1), and Total S&M formula (2); all tier-level formulas pass | | Model Integration | 32 | 28 | Fails the 4-pt criterion for aggregate rows not linked to Silver/Gold/Platinum; all tier-level linkages verified correct | | Output Validation | 44 | 44 | All 11 benchmarks verified within ±2%: Silver Total Cap SAC 2027P = −46.34 ✓, Silver Amortized SAC 2027P = −45.61 ✓, Gold Total Cap SAC 2027P = −19.92 ✓, Platinum Total Cap SAC 2027P = −22.11 ✓, etc. | | Perturbation | 35 | 35 | All 7 tests confirmed at tier-level rows: e.g., Silver cap rate 18%→22% gives G430 = −50.79 ✓; Plat commission rate 10%→15% gives K480 = −31.27 ✓ | | Presentation | 6 | 5 | Missing blue on hardcoded aggregate projection values (−1); dollar format, pct format, black-formula font all pass | | Pitfalls | 0 possible penalty | 0 | No #REF!, #DIV/0!, or other error values found; no truncation issues observed | | **Total** | **143** | **134 (93.7%)** | | **Meridian Rubric Assessment:** | Dimension | Rating | Reasoning | |---|---|---| | Prompt–Workbook Coherence | 5 | Prompt maps cleanly to existing sections; all referenced sales values, subscriber counts, ASPs, and inflation rate link correctly | | Task Feasibility | 5 | Fully executable from the prompt and input workbook | | Input Workbook Starting State | 5 | Professional, complete model with no pre-existing errors | | Output Data Integrity | 5 | No error values; all formulas resolve; no broken references | | Output Formula Quality | 3 | Tier sections are fully dynamic; however 4 consolidation rows covering 5 forecast years are hardcoded rather than formula-driven—this is more than "one or two minor hardcoded values" | | Output Formatting | 4 | Minor inconsistency (missing blue on aggregate hardcoded values; two number-format variants for dollar rows) | | Input-to-Output Progression | 5 | Logical and substantive extension of an operating model | Overall Meridian score: **3 (Acceptable)**. The core deliverable—three complete, formula-driven, correctly structured SAC waterfall sections—is accurately built and fully validated. However, the systematic hardcoding of the projection-period aggregate rows (391, 393, 396, 400) creates a meaningful model-integration gap that prevents downstream financials from updating when assumptions change. This falls short of the "minor weakness" threshold for a 4 but does not trigger an audit-failure condition, placing the task squarely at Acceptable. | D3: 97 | E3: Formula Correctness — Is the aggregate Commission Value and Other SAC Value line computed as the sum of Silver Total Capitalized SAC, Gold Total Capitalized SAC, and Platinum Total Capitalized SAC? Formula Correctness — Is the aggregate Amortized Commissions and Other SAC line computed as the sum of Silver Amortized SAC, Gold Amortized SAC, and Platinum Amortized SAC? Formula Correctness — Is Total Sales and Marketing Costs computed as the sum of Amortized Commissions and Other SAC plus Other S&M? Model Integration — Are Silver, Gold, and Platinum amortization waterfalls linked to each tier’s Total Capitalized SAC row? Model Integration — Are aggregate Commission Value and Other SAC Value and aggregate Amortized Commissions and Other SAC linked to the Silver, Gold, and Platinum sections? Perturbation — If the Platinum Commission Rate for Upgrade/Retention/Downgrade on the Operating Model tab is changed from 10.0% to 15.0% for 2027P, does Platinum Total Capitalized SAC for 2027P in the Sales and Marketing Breakdown by Subscription Type section update to within +/- 2% of -31.27? Perturbation — If the Platinum Other SAC Per Retention/Upgrade on the Operating Model tab is changed from $49.25 to $55.00 for 2022E, does Platinum Total Capitalized SAC for 2023P in the Sales and Marketing Breakdown by Subscription Type section update to within +/- 2% of -2.15? Presentation — Are all dollar-denominated values in the Sales & Marketing Breakdown sections on the Operating Model tab formatted with parentheses for negatives? Pitfalls — Are there any error values in the Operating Model tab (#REF!, #DIV/0!, #VALUE!, #NAME?, #N/A, #NUM!)? Pitfalls — Is any data or label text truncated or hidden due to insufficient column widths or row heights in the Operating Model tab? Formula Correctness — Is the Platinum amortization waterfall spreading each year's capitalized costs over a 3-year useful life with half-year amounts in the first and last periods and full-year amounts in the two middle periods? Formula Correctness — Is Silver Other SAC Per New Sub projected by growing the prior year value at the model’s assumed inflation rate? Presentation — Are formula-driven values displayed in black font (#000000) across the Sales and Marketing Breakdown by Subscription Type section on the Operating Model tab?
A4: Send back to CB - Claude | B4: 3 | C4: # f84b70a6-25e7-4a65-a48f-e49f3d11ee68 **Overall Meridian Score: 3 / 5** **Task-Specific Rubric Score: 87 / 87 (100%)** --- ## Major Takeaways The output workbook adds a new `Valuation` tab to an existing ENTG financial model (Assumptions, Model, Comps). The core structure is present and well-constructed: Trading Liquidity, Public Market Overview, Analyst Ratings, a timetable (2020–2040, annual), P/E Multiple (2025E–2030E, cols O–T), DCF (2025E–2040E, cols O–AD), and a WACC Build section. All key formulas are correct—CoE, weighted average CoD, after-tax CoD, WACC, Gordon Growth Model terminal value, discount factor, and sum-of-cash-flow aggregation. All eight output validation targets and all five perturbation targets in the task-specific rubric are met, and no error values exist anywhere. Arial font and correct number formats are used throughout. However, the output contains three substantive structural failures versus the prompt that the task-specific rubric does not detect: (1) the DCF output rows (Terminal Value → IRR, rows 71–81) are populated only for 2025E (col O) and 2030E–2040E (cols T–AD), leaving four full years (2026E–2029E, cols P–S) completely blank; (2) UFCF YoY growth is hardcoded to 8% for 2031E–2036E but declines to 7%, 6%, 5.5%, and 5% for 2037E–2040E, directly violating the prompt's instruction of 8% for all of 2031E–2040E; and (3) Position Size is hardcoded to 50 while the prompt says 20—however, the rubric perturbation test was calibrated to 50, exposing a prompt factual error. Additionally, an editorial annotation ("<<< 25.0x is significantly lower than sellside…") was left in cell U49. --- ## Major Errors - **Missing DCF output section for 2026E–2029E (cols P, Q, R, S):** Rows 71–81 (Terminal Value, Sum of Cash Flows, PV of Terminal Value, Enterprise Value, Net Debt, Equity Value, FDSO, Implied DCF Price Target, % Upside, IRR) are entirely absent for years 2026E through 2029E. Only col O (2025E) and cols T–AD (2030E–2040E) have these rows populated. The DCF upper rows (Revenue, UFCF, Discount Factor, PV of UFCF, rows 58–66) are correctly populated across all columns. - **UFCF YoY growth not uniformly 8% for 2031E–2040E:** Cells U63–Z63 (2031–2036) are correctly hardcoded at 0.08, but AA63 (2037) = 0.07, AB63 (2038) = 0.06, AC63 (2039) = 0.055, AD63 (2040) = 0.05. The prompt explicitly says to hardcode 8.0% for the entire 2031E–2040E range. Despite the wrong rates, the 2040E DCF outputs land near the rubric-expected values (the expected values appear to have been computed using these declining rates, not uniform 8%). - **Position Size hardcoded at 50 instead of 20:** E11 = 50; the prompt explicitly states "Position Size (hardcode to 20)." This is a prompt factual error—the perturbation test (ADV% 20%→10% yielding days ≈ 2.021) is designed around a position size of 50. A model that correctly followed the prompt and entered 20 would fail that perturbation test (~0.81 days, ~60% off target). - **Extraneous editorial annotation:** U49 contains an inline comment about the exit multiple being below sell-side consensus, which should not appear in a production output workbook. --- ## Critical Errors - **Structural incompleteness of DCF output block (2026E–2029E):** The prompt asks for the "Implied DCF Price Target, % Upside and IRR" (and all prerequisite rows) across the full 2025E–2040E range. Four consecutive years are silently absent. This means the output workbook does not faithfully implement the full DCF-per-year table the prompt describes. - **UFCF growth instruction violated for 2037E–2040E:** Four explicit hardcoded cells deviate from the instruction (8% for all of 2031–2040). The rubric's UFCF-growth formula criterion passes because it only checks the formula structure for 2031E (U61), not the numerical values in 2037–2040. These incorrect rates would cause the 2040E DCF outputs to be wrong if the rubric expected values were actually based on uniform 8% (they are not, but an LLM trained on this task would learn the wrong growth profile). --- ## Rubric Rationale **Task-Specific Rubric (87/87 possible):** | Section | Earned | Available | Notes | |---|---|---|---| | Formula Correctness | 20 | 20 | All 12 formula checks pass: CoE (I94=I91*I92+I93), balance-weighted CoD SUMPRODUCT, AT CoD (H105=H104*(1–25%)), WACC (I107=I86*I94+I87*H105), EV = SUM(E18:E20), Weighted Avg Score SUMPRODUCT, Gordon Growth TV, DCF EV = SUM(O73:O74), Implied PT = Equity/FDSO, Total VPS = SUM(O50:O51), Discount Factor = 1/(1+WACC)^hold, UFCF formula structure | | Model Integration | 4 | 4 | E19 links to Model!BW186+BW187+BW188; those rows are in the Leverage section (starts at row 185) | | Output Validation | 35 | 35 | WACC 8.74% ✓; DCF PT 2040 $176.25 ✓; DCF IRR 2040 4.63% ✓; Total VPS 2030 $218.65 ✓; EV $17,406.60 ✓; Weighted Avg Score 2.571 ✓; PV TV 2040 $18,940 ✓; UFCF 2025 $557.6 ✓ | | Perturbation | 25 | 25 | Beta 1.50→new WACC 9.16%, formulas live; ERP 5% updates CoE dynamically; UFCF 2031 10% ratio = 1.10/1.08 → ~$179.51 within 2%; TGR links via Assumptions!E45→G45; ADV% 10% with PS=50 gives exactly 2.021 days | | Presentation | 3 | 3 | IRR format `#,##0.0%`, per-share `#,##0.00`, Arial confirmed on all sampled cells | | Pitfalls | 0 | (max –8) | No error values in Valuation or Assumptions tabs; U49 annotation not treated as required-data truncation | **Meridian Rubric Assessment:** - **Prompt quality:** ~3 — well-structured and mostly complete, but contains a clear factual error (position size 20 stated vs. 50 in golden output), and the UFCF "hardcode to 8% for 2031–2040" instruction contradicts the declining rates in the output. - **Input Workbook:** 4–5 — clean professional ENTG model with no errors, appropriate starting state. - **Output Workbook:** 3 — no errors, professional formatting, correct formulas, but structurally incomplete (4 DCF years missing) and violates two explicit prompt instructions (UFCF growth uniformity, position size). - **Rubric:** 3 — internally self-consistent against the actual output; factually correct for the output values tested; however, it does not test UFCF growth uniformity (2037–2040), does not flag the missing DCF columns, and contains the same position-size inconsistency as the prompt. **Overall: 3 — Acceptable.** The task passes audit (no error values, core structural sections present, rubric criteria internally consistent), but it has noticeable structural gaps and prompt factual errors that prevent a score of 4. | D4: 100

Sheet Model Decomp
A1: Task ID | B1: Seed ID | C1: Claimed By | D1: Force Claim Link | E1: Prompt Done? | F1: Checked FC / MI | G1: Date Completed | H1: AHT (mins) | I1: Rubric to Paste and Edit | J1: Rubric Reviewer | K1: OV/PT/Pres/Pitfalls Checked? | L1: Date Completed | M1: AHT (mins) - Post Prompt | N1: Admin Link Helper | O1: Checked? | P1: Notes | Q1: SOTA (Est.) | R1: Notes | T1: 46160 | U1: =countifs(E:E,true,G:G,$T1) -> 2 | V1: =countifs(K:K,true,L:L,$T1) -> 2
A2: 89eae8f1-dc6f-4145-a072-f056af902c05 | B2: 85d3d5d5-f85d-4799-8504-b807ad61ed36 | C2: Jalaj G | D2: =concat("https://www.tsip.ai/force/",A2) -> https://www.tsip.ai/force/89eae8f1-dc6f-4145-a072-f056af902c05 | E2: TRUE | F2: FALSE | G2: 46161 | H2: 50 | I2: =iferror(VLOOKUP(A2,'Decomp Rubrics'!A:B,2,false),"generating") -> generating | K2: FALSE | N2: ="https://admin.tsip.ai/tasks/"&A2 -> https://admin.tsip.ai/tasks/89eae8f1-dc6f-4145-a072-f056af902c05 | O2: FALSE | T2: 46161 | U2: =countifs(E:E,true,G:G,$T2) -> 7 | V2: =countifs(K:K,true,L:L,$T2) -> 0
A3: 2130b610-dc4c-4605-9163-a8b2224abd06 | B3: 09e67384-2f7f-4070-abcb-4ed9a2f4545e | C3: Jalaj G | D3: =concat("https://www.tsip.ai/force/",A3) -> https://www.tsip.ai/force/2130b610-dc4c-4605-9163-a8b2224abd06 | E3: TRUE | F3: TRUE | G3: 46162 | H3: 55 | I3: =iferror(VLOOKUP(A3,'Decomp Rubrics'!A:B,2,false),"generating") -> Section 1: Formula Correctness 1.1. Is Total Cost in the main project table on the Gross Margin tab calculated as the sum of Project-Level Cost and Client-Level Cost Allocation for each project? [+2] 1.2. Is Gross Profit in the main project table on the Gross Margin tab calculated as Project Value minus Total Cost for each project? [+2] 1.3. Is Gross Margin in the main project table on the Gross Margin tab calculated as Gross Profit divided by Project Value for each project? [+1] 1.4. Is the Total row Gross Margin on the Gross Margin tab calculated as total Gross Profit divided by total Project Value, rather than as an average of individual project margins? [+2] 1.5. Is the Average row Gross Margin on the Gross Margin tab calculated as average Gross Profit divided by average Project Value, not as the average of individual margins? [+2] 1.6. Does the Total row on the Gross Margin tab sum all 20 projects for Project Value, Hours at Project Level, Project-Level Cost, Client-Level Cost Allocation, Total Cost, and Gross Profit? [+2] 1.7. Does the Average row on the Gross Margin tab compute the arithmetic mean across all 20 projects for each numeric column (value, hours, costs, gross profit)? [+1] 1.8. Is the percentage-of-total column in each client allocation subtable on the Gross Margin tab calculated as that project's Project-Level Cost divided by the client's total Project-Level Cost? [+2] 1.9. Is the Client Level Cost Allocation per project in each client subtable on the Gross Margin tab calculated as the project's percentage of total cost multiplied by the client's total non-project-level cost? [+2] 1.10. Does the total row within each client allocation subtable on the Gross Margin tab sum Hours and Project-Level Cost across all projects listed in that client block? [+1] 1.11. Are Hours in the non-project-level time section on the Gross Margin tab aggregated from Harvest Data by matching both client name and the exact label 'Time not at Project Level' in Project Phase? [+2] 1.12. Is Client-Level Cost in the non-project-level time section on the Gross Margin tab aggregated from Harvest Data's Grossed Extended Cost column using the same dual-filter on client name and Project Phase? [+2] 1.13. Is the Client-Level Cost Allocation in the main table hardcoded to zero for projects belonging to clients with no non-project-level overhead (H&M, Panda Express, Red Sky, Vision Food Group)? [+2] 1.14. Is the Client-Level Cost Allocation for School of Rock's single project in the main table a direct reference to that client's total non-project-level cost rather than a subtable lookup? [+1] Section 2: Model Integration 2.1. Is the Hours at Project Level on the Gross Margin - Completed Projec tab linked to the Grossed Up Hours on the Harvest Data tab? [+5] 2.2. Is the Project Start Date on the Gross Margin - Completed Projec tab linked to the Actual start date (Permit Ops) on the Projects tab? [+3] Section 3: Output Validation 3.1. Is the Total Gross Profit on the Gross Margin - Completed Projec tab (Total row, column L) within +/- 2% of 898393.31? [+5] 3.2. Is the Total Gross Margin on the Gross Margin - Completed Projec tab (Total row, column M) within +/- 0.5 pp of 64.8%? [+5] 3.3. Is the Average Gross Profit on the Gross Margin - Completed Projec tab (Average row, column L) within +/- 2% of 44919.67? [+5] 3.4. Is the Total Project-Level Cost on the Gross Margin - Completed Projec tab (Total row, column I) within +/- 2% of 449498.69? [+4] 3.5. Is the Total Client-Level Cost Allocation on the Gross Margin - Completed Projec tab (Total row, column J) within +/- 2% of 39000? [+5] 3.6. Is the Total Hours at Project Level on the Gross Margin - Completed Projec tab (Total row, column H) within +/- 2% of 7858.18? [+3] 3.7. Is the Total Total Cost on the Gross Margin - Completed Projec tab (Total row, column K) within +/- 2% of 488498.69? [+5] 3.8. Is the Total Project Value on the Gross Margin - Completed Projec tab (Total row, column G) within +/- 2% of 1386892? [+3] 3.9. Is the Average Gross Margin on the Gross Margin - Completed Projec tab (Average row, column M) within +/- 0.5 pp of 64.7%? [+5] Section 4: Perturbation 4.1. If the Grossed Extended Cost value for the first data row in the Harvest Data tab (the row with task ID 15485439, Grossed Extended Cost of approximately 1034.81) is changed from 1034.8128 to 2069.6256 (doubled), does the Total Project-Level Cost on the Gross Margin - Completed Projec tab (Total row) update to reflect the increase, within +/- 2% of the correctly computed value? [+5] 4.2. If the Grossed Up Hours value for the first data row in the Harvest Data tab (the row with Grossed Up Hours of 8) is changed from 8 to 24 (tripled), does the Total Hours at Project Level on the Gross Margin - Completed Projec tab (Total row) update to reflect the increase, within +/- 2% of the correctly computed value? [+5] 4.3. If the Grossed Extended Cost value on the Harvest Data tab in the second data row (approximately 381.19) is changed from 381.1872 to 762.3744 (doubled), does the Total Gross Profit on the Gross Margin - Completed Projec tab (Total row) update to reflect the increased cost reducing profit, within +/- 2% of the correctly computed value? [+5] 4.4. If the Grossed Extended Cost value on the Harvest Data tab in the third data row (approximately 735.19) is changed from 735.1872 to 1470.3744 (doubled), does the Total row Gross Margin percentage on the Gross Margin - Completed Projec tab update to reflect the reduced margin, within +/- 0.5 percentage points of the correctly computed value? [+5] 4.5. If the Grossed Up Hours value on the Harvest Data tab in the second data row (value of 8) is changed from 8 to 40 (5x), does the Average Hours at Project Level on the Gross Margin - Completed Projec tab (Average row) update to reflect the increase, within +/- 2% of the correctly computed value? [+5] 4.6. If the Grossed Extended Cost for the fourth data row on the Harvest Data tab (approximately 129.35, column AM row index corresponding to the fourth upstream constant at AB3's paired cost) is changed from 1034.8128 to 0 (zeroed out), does the Total Cost on the Gross Margin - Completed Projec tab (Total row) update to reflect the decrease, within +/- 2% of the correctly computed value? [+5] 4.7. If the Grossed Extended Cost on the Harvest Data tab in the third data row (approximately 735.19) is changed from 735.1872 to 0 (zeroed out), does the Average Gross Profit on the Gross Margin - Completed Projec tab (Average row) update to reflect the improved profitability, within +/- 2% of the correctly computed value? [+5] Section 5: Presentation 5.1. Are all dollar-denominated values on the Gross Margin - Completed Projec tab formatted with a dollar sign prefix, comma separators, and no decimal places? [+2] 5.2. Do hardcoded values on the Gross Margin - Completed Projec tab appear in blue font, formula-driven values in black font, and cross-sheet references in green font? [+2] 5.3. Are the Total and Average rows and client-subtable total rows on the Gross Margin - Completed Projec tab visually distinguished with bold text? [+2] Section 6: Pitfalls 6.1. Are there any error values in the Internal Metrics tab and the Gross Margin - Completed Projec tab (#REF!, #DIV/0!, #VALUE!, #NAME?, #N/A, #NUM!)? [-5] 6.2. Is any data or label text truncated due to insufficient column widths or row heights in the Internal Metrics tab and the Gross Margin - Completed Projec tab? [-3] | K3: TRUE | L3: 46162 | M3: 65 | N3: ="https://admin.tsip.ai/tasks/"&A3 -> https://admin.tsip.ai/tasks/2130b610-dc4c-4605-9163-a8b2224abd06 | O3: FALSE | T3: 46162 | U3: =countifs(E:E,true,G:G,$T3) -> 20 | V3: =countifs(K:K,true,L:L,$T3) -> 12
A4: 6520d1cb-ef7f-4e18-8e27-901c61b13a4b | B4: 8bcd0914-32d4-4fc9-b97e-3c0c61e9c9ae | C4: Jalaj G | D4: =concat("https://www.tsip.ai/force/",A4) -> https://www.tsip.ai/force/6520d1cb-ef7f-4e18-8e27-901c61b13a4b | E4: TRUE | F4: FALSE | G4: 46161 | H4: 65 | I4: =iferror(VLOOKUP(A4,'Decomp Rubrics'!A:B,2,false),"generating") -> generating | K4: FALSE | N4: ="https://admin.tsip.ai/tasks/"&A4 -> https://admin.tsip.ai/tasks/6520d1cb-ef7f-4e18-8e27-901c61b13a4b | O4: FALSE | T4: 46163 | U4: =countifs(E:E,true,G:G,$T4) -> 8 | V4: =countifs(K:K,true,L:L,$T4) -> 6
A5: f0ec3331-b842-4f0f-bc7a-b3aa14727aa1 | B5: 8bcd0914-32d4-4fc9-b97e-3c0c61e9c9ae | C5: Jalaj G | D5: =concat("https://www.tsip.ai/force/",A5) -> https://www.tsip.ai/force/f0ec3331-b842-4f0f-bc7a-b3aa14727aa1 | E5: TRUE | F5: FALSE | G5: 46161 | H5: 65 | I5: =iferror(VLOOKUP(A5,'Decomp Rubrics'!A:B,2,false),"generating") -> generating | K5: FALSE | N5: ="https://admin.tsip.ai/tasks/"&A5 -> https://admin.tsip.ai/tasks/f0ec3331-b842-4f0f-bc7a-b3aa14727aa1 | O5: FALSE | T5: 46164 | U5: =countifs(E:E,true,G:G,$T5) -> 0 | V5: =countifs(K:K,true,L:L,$T5) -> 0
A6: cb5b1a21-8bce-42c1-807f-d08dcf9df983 | B6: 848b60ba-8233-45dd-a962-e6ba852d7b60 | C6: Jalaj G | D6: =concat("https://www.tsip.ai/force/",A6) -> https://www.tsip.ai/force/cb5b1a21-8bce-42c1-807f-d08dcf9df983 | E6: TRUE | F6: FALSE | G6: 46161 | H6: 55 | I6: =iferror(VLOOKUP(A6,'Decomp Rubrics'!A:B,2,false),"generating") -> generating | K6: FALSE | N6: ="https://admin.tsip.ai/tasks/"&A6 -> https://admin.tsip.ai/tasks/cb5b1a21-8bce-42c1-807f-d08dcf9df983 | O6: FALSE
A7: 4ebd8dfe-d037-41fa-914c-0a150d04cb87 | B7: 848b60ba-8233-45dd-a962-e6ba852d7b60 | C7: Jalaj G | D7: =concat("https://www.tsip.ai/force/",A7) -> https://www.tsip.ai/force/4ebd8dfe-d037-41fa-914c-0a150d04cb87 | E7: TRUE | F7: FALSE | G7: 46161 | H7: 65 | I7: =iferror(VLOOKUP(A7,'Decomp Rubrics'!A:B,2,false),"generating") -> generating | K7: FALSE | N7: ="https://admin.tsip.ai/tasks/"&A7 -> https://admin.tsip.ai/tasks/4ebd8dfe-d037-41fa-914c-0a150d04cb87 | O7: FALSE
A8: 212df67f-c687-4e67-afe9-50edeaab2592 | B8: 874f82c0-6de1-4a82-8270-2c8d51e3dddc | C8: Jared M | D8: =concat("https://www.tsip.ai/force/",A8) -> https://www.tsip.ai/force/212df67f-c687-4e67-afe9-50edeaab2592 | E8: TRUE | F8: TRUE | G8: 46161 | H8: 90 | I8: =iferror(VLOOKUP(A8,'Decomp Rubrics'!A:B,2,false),"generating") -> generating | K8: TRUE | L8: 46162 | M8: 60 | N8: ="https://admin.tsip.ai/tasks/"&A8 -> https://admin.tsip.ai/tasks/212df67f-c687-4e67-afe9-50edeaab2592 | O8: FALSE
A9: 53f5ed76-f45f-4c3d-986c-2aa0015a4bc0 | B9: 874f82c0-6de1-4a82-8270-2c8d51e3dddc | C9: Ava Z | D9: =concat("https://www.tsip.ai/force/",A9) -> https://www.tsip.ai/force/53f5ed76-f45f-4c3d-986c-2aa0015a4bc0 | E9: TRUE | F9: TRUE | G9: 46161 | H9: 150 | I9: Section 1: Formula Correctness 1.1. Is Total New Subscribers in the Core Metrics section on the Revenue Detail tab calculated as the sum of New Annual Subscribers, New Monthly Subscribers, and New Advisor Subscribers? [+2] 1.2. Is Total Subscribers in the Core Metrics section on the Revenue Detail tab calculated as the sum of Annual Subscribers, Monthly Subscribers, and Advisor Subscribers? [+2] 1.3. Is Total ARR in the ARR Summary section on the Revenue Detail tab calculated as the sum of Annual ARR, Monthly ARR, Advisors ARR, and Other ARR? [+2] 1.4. Is Total Revenue in the grand total section on the Revenue Detail tab calculated as the sum of Total Annual+Monthly Revenue, Advisor Revenue, Net Refunds, and Other Revenue? [+2] 1.5. Is Total Revenue in the Annual+Monthly section on the Revenue Detail tab calculated as the sum of Annual Subscription Revenue and Monthly Subscription Revenue? [+1] 1.6. Is Total Billings in the Annual+Monthly section on the Revenue Detail tab calculated as the sum of Annual Billings and Monthly Billings? [+1] 1.7. Is Expansion Billings Only in the Annual+Monthly section on the Revenue Detail tab calculated as the sum of Annual Upgrade Billings and Monthly Upgrade Billings? [+1] 1.8. Is Billings - Monthly on the Revenue Detail tab derived as the simple average of the current period's and next period's Monthly Subscription Revenue rather than a direct sum of billing components? [+2] 1.9. Is the Monthly Conversion to Tier A rate on the Revenue Detail tab capped at 40% using conditional logic that increments by 1 percentage point per period after the initial zero-rate periods? [+3] 1.10. Is Monthly Renewed Subscriber Billings on the Revenue Detail tab derived as total monthly billings minus new subscriber billings (a back-into calculation) rather than a build-up? [+2] 1.11. Is the Monthly ending subscriber rollforward on the Revenue Detail tab computed as beginning subscribers plus new subscribers plus renewals minus churned subscribers? [+2] 1.12. Is Average Revenue per Sub per Month in Core Metrics on the Revenue Detail tab calculated as Total Revenue minus Other Revenue minus Net Refunds minus Advisor Revenue, divided by the sum of ending Annual and Monthly subscribers? [+2] 1.13. Is Total Deferred Revenue in the Deferred Revenue section on the Revenue Detail tab calculated as the sum of Total Annual+Monthly Deferred Revenue, Advisor Deferred Revenue, and Lifetime Deferred Revenue? [+2] 1.14. Is Total Refund % of 12 Mo Billings in the Disputes and Refunds section on the Revenue Detail tab calculated as Total Refunds Pool divided by a trailing 12-month rolling sum of annual billings? [+3] 1.15. Is ARR Growth % in the KPI header area on the Revenue Detail tab calculated as the period-over-period percentage change in the Total ARR line? [+1] Section 2: Model Integration 2.1. Is the Average Billing Rate in the Monthly Subscribers section on the Revenue Detail tab linked to the Monthly Billing Rate on the Omni tab? [+3] 2.2. Is the Subscription Revenue in the Monthly Subscribers section on the Revenue Detail tab linked to the Total Monthly Subscriptions on the Actuals P&L tab? [+3] 2.3. Is the Renewed Subscriber Billings in the Monthly Subscribers section on the Revenue Detail tab linked to the Total Monthly Billings on the Omni tab? [+3] 2.4. Is the Total Deferred Revenue in the Annual plus Monthly section on the Revenue Detail tab linked to the platform deferred revenue lines on the Actuals BS tab? [+3] 2.5. Is the Net Refunds on the Revenue Detail tab linked to the refund and dispute lines on the Actuals P&L tab? [+3] 2.6. Is the Lifetime Deferred Revenue on the Revenue Detail tab linked to the Lifetime membership deferred revenue on the Actuals BS tab? [+2] Section 3: Output Validation 3.1. Is Total ARR on the Revenue Detail tab in the final forecast period (column BP) within +/- 2% of 8,964,888? [+5] 3.2. Is Total Subscribers on the Revenue Detail tab in the final forecast period (column BP) within +/- 2% of 36,498? [+5] 3.3. Is Annualized Billings on the Revenue Detail tab in the final forecast period (column BP) within +/- 2% of 9,082,860? [+5] 3.4. Is Total New Subscribers on the Revenue Detail tab in the last actuals period (column BJ) within +/- 2% of 951? [+5] 3.5. Is Total Deferred Revenue on the Revenue Detail tab in the last actuals period (column BJ) within +/- 2% of 353,498.07? [+5] 3.6. Is Expansion Billings Only on the Revenue Detail tab in the last actuals period (column BJ) within +/- 2% of 20,044.09? [+4] 3.7. Is Total Revenue on the Revenue Detail tab in period 35 within +/- 2% of 432,093.08? [+4] 3.8. Is ARR Growth % on the Revenue Detail tab in the last actuals period within +/- 0.5 pp of 2.7%? [+3] 3.9. Is Total ARR on the Revenue Detail tab in period 25 (column AA) within +/- 2% of 3,389,400? [+3] Section 4: Perturbation 4.1. If the Annual Subscription starting subscribers value on the Revenue Detail tab (period 1, currently 8251) is changed to 16502, does Total Subscribers on the Revenue Detail tab in the Core Metrics section for the same period update to within +/- 2% of the expected value reflecting the doubled annual subscriber count? [+5] 4.2. If the Upgrade Price of Tier A for Monthly Subscribers on the Revenue Detail tab is changed from 19.99 to 39.98 (doubled), does Expansion Billings Only in the Total - Annual + Monthly section update to within +/- 2% of the expected value reflecting doubled monthly upgrade pricing for the final projected period? [+5] 4.3. If the Conversion to Tier A rate for Monthly Subscribers on the Revenue Detail tab is changed from 0% to 20% in the first ramp period (column AC), does Monthly Upgrade Billings for that same period update to within +/- 2% of the expected value reflecting the 20% conversion rate? [+5] 4.4. If the Apple Deferred Revenue balance on the Actuals BS tab for the latest actuals period (column AA) is changed from its current value of 0 to 500000, does Total Deferred Revenue in the Deferred Revenue summary section on the Revenue Detail tab for the corresponding period update to within +/- 2% of the expected value reflecting the 500000 addition? [+5] 4.5. If the ending monthly subscriber count hardcoded on the Revenue Detail tab for period L (currently 894) is changed to 1788 (doubled), does Total Subscribers Excluding Advisory in the Core Metrics section for the same period update to within +/- 2% of the expected value reflecting the doubled monthly subscriber base? [+5] 4.6. If the Sponsor subscriber conversion rate (Converts in Same Month fraction) on the Revenue Detail tab is changed from 0.71 to 0.35 (halved) in column AB, does Total New Subscribers in the Core Metrics section for that period update to within +/- 2% of the expected value reflecting the reduced conversion fraction? [+5] 4.7. If the Annual ending subscriber count hardcoded on the Revenue Detail tab for period Y (currently 7426) is changed to 3713 (halved), does the Average Revenue per Sub per Month in the Revenue per Sub (Excl Advisors) Core Metrics section for that period update to within +/- 2% of the expected value reflecting the halved annual subscriber denominator? [+5] Section 5: Presentation 5.1. Are hardcoded values on the Revenue Detail tab displayed in blue font, formula-driven values in black font, and cross-sheet references in green font? [+2] 5.2. Are dollar-denominated values in the new sections on the Revenue Detail tab formatted with a dollar sign prefix and comma separators with no decimal places, consistent with the existing Annual Subscribers section? [+2] 5.3. Are percentage rows in the new sections on the Revenue Detail tab formatted as percentages with one decimal place, consistent with the existing growth rate and mix rows? [+2] Section 6: Pitfalls 6.1. Are there any error values in the Revenue Detail tab (#REF!, #DIV/0!, #VALUE!, #NAME?, #N/A, #NUM!)? [-5] 6.2. Is any data or label text truncated due to insufficient column widths or row heights in the Revenue Detail tab? [-3] | K9: TRUE | L9: 46162 | M9: 90 | N9: ="https://admin.tsip.ai/tasks/"&A9 -> https://admin.tsip.ai/tasks/53f5ed76-f45f-4c3d-986c-2aa0015a4bc0 | O9: FALSE
A10: 0cf86c7d-efd2-449c-ba36-fd3f8ef9d235 | B10: 874f82c0-6de1-4a82-8270-2c8d51e3dddc | C10: Jared M | D10: =concat("https://www.tsip.ai/force/",A10) -> https://www.tsip.ai/force/0cf86c7d-efd2-449c-ba36-fd3f8ef9d235 | E10: TRUE | F10: TRUE | G10: 46162 | H10: 15 | K10: TRUE | L10: 46162 | M10: 45 | N10: ="https://admin.tsip.ai/tasks/"&A10 -> https://admin.tsip.ai/tasks/0cf86c7d-efd2-449c-ba36-fd3f8ef9d235 | O10: FALSE
